Workbook

Sheet CSDL_Truong
A1: CƠ SỞ DỮ LIỆU THUỘC TÍNH VÀ THUẬT TOÁN ĐÁNH GIÁ 7 TIÊU CHÍ AHP - CÁ NHÂN HÓA WEB-GIS TRƯỜNG THPT
A2: STT | B2: Ten_Truong | C2: Dia_Chi | D2: Loai_Hinh | E2: CT_GDPT_2018 | F2: Latitude | G2: Longitude | H2: Diem_Chuan_2026 | I2: Diem_Chuan_TB_3Nam | J2: Chi_Tieu | K2: Ty_Le_Choi | L2: Hoc_2_Buoi | M2: Ban_Tru | N2: Hoc_Phi_Thang | O2: Tuyen_Xe_Buyt | P2: CLB_Noi_Bat | Q2: Website_Truong | R2: Khoang_Cach_km | S2: c1_Chat_Luong | T2: c2_Moi_Truong_CSVC | U2: c3_Dinh_Huong_Mon | V2: c4_Kha_Nang_Trung_Tuyen | W2: c5_Tai_Chinh | X2: c6_Vi_Tri_Di_Chuyen | Y2: c7_Mo_Hinh_Ban_Tru | Z2: Diem_Tuong_Thich_S | AA2: Xep_Hang
A3: 1 | B3: THPT Nguyễn Du | C3: XX1 Đường Đồng Nai, Phường Hòa Hưng, Tp. HCM | D3: Công lập | E3: Có | F3: 10.779094 | G3: 106.66238 | H3: 21.75 | I3: 20 | J3: 595 | K3: 1.38 | L3: Có | M3: Có | N3: 1767000 | O3: 38, 59, 69, 103 | P3: Truyền thông, Nhảy hiện đại (The Castillo), Âm nhạc (The... | Q3: https://thptnguyendu.hcm.edu.vn/ | R3: =TINHKHOANGCACH(Ho_So_Hoc_Sinh!$B$3, C3) -> #NAME? | S3: =IF(ISBLANK(K3), 7, MIN(10, K3 * 4.5)) -> 6.21 | T3: =IF(L3="Có", 10, 6) -> 10 | U3: =Ho_So_Hoc_Sinh!$B$8 -> 10 | V3: =IF(ISBLANK(H3), 7.5, IF(Ho_So_Hoc_Sinh!$B$4>=H3+1, 10, IF(Ho_So_Hoc_Sinh!$B$4<H3-1, 0, 10 - 5*(H3+1-Ho_So_Hoc_Sinh!$B$4)))) -> 1.25 | W3: =IF(D3="Công lập", 10, 5) -> 10 | X3: =MAX(0, 10*(1 - R3/10)) -> #NAME? | Y3: =IF(Ho_So_Hoc_Sinh!$B$5=0, 10, IF(M3="Có", 10, 0)) -> 10 | Z3: =0.154*S3 + 0.152*T3 + 0.145*U3 + 0.144*V3 + 0.14*W3 + 0.138*X3 + 0.128*Y3 -> #NAME? | AA3: =IF(RANK(Z3, $Z$3:$Z$48)=1, "Top 1", IF(RANK(Z3, $Z$3:$Z$48)=2, "Top 2", IF(RANK(Z3, $Z$3:$Z$48)=3, "Top 3", "Khác"))) -> #NAME?
A4: 2 | B4: THCS-THPT Diên Hồng | C4: 11 Thành Thái, Phường Diên Hồng, Tp. HCM | D4: Công lập | E4: Có | F4: 10.770551 | G4: 106.66548 | H4: 15 | I4: 13.92 | J4: 450 | K4: 0.51 | L4: Có | M4: Có | N4: 200000 | O4: 38, 59, 69, 103 | P4: Văn nghệ, Học thuật - Truyền Thông, các CLB thể thao,... | Q4: https://thptdienhong.hcm.edu.vn | R4: =TINHKHOANGCACH(Ho_So_Hoc_Sinh!$B$3, C4) -> #NAME? | S4: =IF(ISBLANK(K4), 7, MIN(10, K4 * 4.5)) -> 2.295 | T4: =IF(L4="Có", 10, 6) -> 10 | U4: =Ho_So_Hoc_Sinh!$B$8 -> 10 | V4: =IF(ISBLANK(H4), 7.5, IF(Ho_So_Hoc_Sinh!$B$4>=H4+1, 10, IF(Ho_So_Hoc_Sinh!$B$4<H4-1, 0, 10 - 5*(H4+1-Ho_So_Hoc_Sinh!$B$4)))) -> 10 | W4: =IF(D4="Công lập", 10, 5) -> 10 | X4: =MAX(0, 10*(1 - R4/10)) -> #NAME? | Y4: =IF(Ho_So_Hoc_Sinh!$B$5=0, 10, IF(M4="Có", 10, 0)) -> 10 | Z4: =0.154*S4 + 0.152*T4 + 0.145*U4 + 0.144*V4 + 0.14*W4 + 0.138*X4 + 0.128*Y4 -> #NAME? | AA4: =IF(RANK(Z4, $Z$3:$Z$48)=1, "Top 1", IF(RANK(Z4, $Z$3:$Z$48)=2, "Top 2", IF(RANK(Z4, $Z$3:$Z$48)=3, "Top 3", "Khác"))) -> #NAME?
A5: 3 | B5: THPT Nguyễn Khuyến | C5: 50 Thành Thái, Phường Hòa Hưng, Tp. HCM | D5: Công lập | E5: Có | F5: 10.769635 | G5: 106.66667 | H5: 20.75 | I5: 19.25 | J5: 855 | K5: 1.18 | L5: Có | M5: Có | N5: 200000 | O5: 38, 59, 69, 103 | P5: Văn nghệ, Học thuật - Truyền Thông, các CLB thể thao,... | Q5: https://thptnguyenkhuyen.hcm.edu.vn | R5: =TINHKHOANGCACH(Ho_So_Hoc_Sinh!$B$3, C5) -> #NAME? | S5: =IF(ISBLANK(K5), 7, MIN(10, K5 * 4.5)) -> 5.31 | T5: =IF(L5="Có", 10, 6) -> 10 | U5: =Ho_So_Hoc_Sinh!$B$8 -> 10 | V5: =IF(ISBLANK(H5), 7.5, IF(Ho_So_Hoc_Sinh!$B$4>=H5+1, 10, IF(Ho_So_Hoc_Sinh!$B$4<H5-1, 0, 10 - 5*(H5+1-Ho_So_Hoc_Sinh!$B$4)))) -> 6.25 | W5: =IF(D5="Công lập", 10, 5) -> 10 | X5: =MAX(0, 10*(1 - R5/10)) -> #NAME? | Y5: =IF(Ho_So_Hoc_Sinh!$B$5=0, 10, IF(M5="Có", 10, 0)) -> 10 | Z5: =0.154*S5 + 0.152*T5 + 0.145*U5 + 0.144*V5 + 0.14*W5 + 0.138*X5 + 0.128*Y5 -> #NAME? | AA5: =IF(RANK(Z5, $Z$3:$Z$48)=1, "Top 1", IF(RANK(Z5, $Z$3:$Z$48)=2, "Top 2", IF(RANK(Z5, $Z$3:$Z$48)=3, "Top 3", "Khác"))) -> #NAME?
A6: 4 | B6: THPT Nguyễn An Ninh | C6: 93, Trần Nhân Tôn, Phường Vườn Lài, Tp. HCM | D6: Công lập | E6: Có | F6: 10.761618 | G6: 106.67416 | H6: 16.25 | I6: 15.08 | J6: 900 | K6: 0.69 | L6: Có | M6: Có | N6: 200000 | O6: 38, 45, 69, 91, 139 | P6: Học thuật, Công tác xã hội (Chuồn Chuồn), Nhảy hiện đại... | Q6: https://thptnguyenanninh.hcm.edu.vn/ | R6: =TINHKHOANGCACH(Ho_So_Hoc_Sinh!$B$3, C6) -> #NAME? | S6: =IF(ISBLANK(K6), 7, MIN(10, K6 * 4.5)) -> 3.105 | T6: =IF(L6="Có", 10, 6) -> 10 | U6: =Ho_So_Hoc_Sinh!$B$8 -> 10 | V6: =IF(ISBLANK(H6), 7.5, IF(Ho_So_Hoc_Sinh!$B$4>=H6+1, 10, IF(Ho_So_Hoc_Sinh!$B$4<H6-1, 0, 10 - 5*(H6+1-Ho_So_Hoc_Sinh!$B$4)))) -> 10 | W6: =IF(D6="Công lập", 10, 5) -> 10 | X6: =MAX(0, 10*(1 - R6/10)) -> #NAME? | Y6: =IF(Ho_So_Hoc_Sinh!$B$5=0, 10, IF(M6="Có", 10, 0)) -> 10 | Z6: =0.154*S6 + 0.152*T6 + 0.145*U6 + 0.144*V6 + 0.14*W6 + 0.138*X6 + 0.128*Y6 -> #NAME? | AA6: =IF(RANK(Z6, $Z$3:$Z$48)=1, "Top 1", IF(RANK(Z6, $Z$3:$Z$48)=2, "Top 2", IF(RANK(Z6, $Z$3:$Z$48)=3, "Top 3", "Khác"))) -> #NAME?
A7: 5 | B7: THCS-THPT Sương Nguyệt Anh | C7: 249 Hoà Hảo, Phường Vườn Lài, Tp. HCM | D7: Công lập | E7: Có | F7: 10.76229 | G7: 106.67099 | H7: 13.5 | I7: 13 | J7: 450 | K7: 0.33 | L7: Có | M7: Có | N7: 200000 | O7: 05, 10, 45, 69, 150 | P7: Hùng biện Tiếng Anh, Nghệ thuật, các CLB thể thao,... | Q7: https://thptsuongnguyetanh.hcm.edu.vn | R7: =TINHKHOANGCACH(Ho_So_Hoc_Sinh!$B$3, C7) -> #NAME? | S7: =IF(ISBLANK(K7), 7, MIN(10, K7 * 4.5)) -> 1.485 | T7: =IF(L7="Có", 10, 6) -> 10 | U7: =Ho_So_Hoc_Sinh!$B$8 -> 10 | V7: =IF(ISBLANK(H7), 7.5, IF(Ho_So_Hoc_Sinh!$B$4>=H7+1, 10, IF(Ho_So_Hoc_Sinh!$B$4<H7-1, 0, 10 - 5*(H7+1-Ho_So_Hoc_Sinh!$B$4)))) -> 10 | W7: =IF(D7="Công lập", 10, 5) -> 10 | X7: =MAX(0, 10*(1 - R7/10)) -> #NAME? | Y7: =IF(Ho_So_Hoc_Sinh!$B$5=0, 10, IF(M7="Có", 10, 0)) -> 10 | Z7: =0.154*S7 + 0.152*T7 + 0.145*U7 + 0.144*V7 + 0.14*W7 + 0.138*X7 + 0.128*Y7 -> #NAME? | AA7: =IF(RANK(Z7, $Z$3:$Z$48)=1, "Top 1", IF(RANK(Z7, $Z$3:$Z$48)=2, "Top 2", IF(RANK(Z7, $Z$3:$Z$48)=3, "Top 3", "Khác"))) -> #NAME?
A8: 6 | B8: THCS-THPT Duy Tân | C8: 106 Nguyễn Giản Thanh, Phường Hoà Hưng, Tp. HCM | D8: Tư thục | E8: Có | F8: 10.783253 | G8: 106.66286 | L8: Có | M8: Có | N8: 200000 | O8: 05, 10, 27, 38, 50, 69, 103, 148, 150 | P8: Học thuật - Nghệ thuật - Thể thao, Liên kết lập trình viên... | Q8: https://thptduytan.hcm.edu.vn | R8: =TINHKHOANGCACH(Ho_So_Hoc_Sinh!$B$3, C8) -> #NAME? | S8: =IF(ISBLANK(K8), 7, MIN(10, K8 * 4.5)) -> 7 | T8: =IF(L8="Có", 10, 6) -> 10 | U8: =Ho_So_Hoc_Sinh!$B$8 -> 10 | V8: =IF(ISBLANK(H8), 7.5, IF(Ho_So_Hoc_Sinh!$B$4>=H8+1, 10, IF(Ho_So_Hoc_Sinh!$B$4<H8-1, 0, 10 - 5*(H8+1-Ho_So_Hoc_Sinh!$B$4)))) -> 7.5 | W8: =IF(D8="Công lập", 10, 5) -> 5 | X8: =MAX(0, 10*(1 - R8/10)) -> #NAME? | Y8: =IF(Ho_So_Hoc_Sinh!$B$5=0, 10, IF(M8="Có", 10, 0)) -> 10 | Z8: =0.154*S8 + 0.152*T8 + 0.145*U8 + 0.144*V8 + 0.14*W8 + 0.138*X8 + 0.128*Y8 -> #NAME? | AA8: =IF(RANK(Z8, $Z$3:$Z$48)=1, "Top 1", IF(RANK(Z8, $Z$3:$Z$48)=2, "Top 2", IF(RANK(Z8, $Z$3:$Z$48)=3, "Top 3", "Khác"))) -> #NAME?
A9: 7 | B9: TH-THCS-THPT Vạn Hạnh | C9: 781E Lê Hồng Phong, Phường Hoà Hưng, Tp. HCM | D9: Tư thục | E9: Có | F9: 10.772052 | G9: 106.67077 | L9: Có | M9: Có | N9: 4000000 | O9: 05, 10, 27, 38, 50, 69, 103, 148, 150 | P9: Văn hoá, Nghệ thuật, các CLB thể thao,... | Q9: https://thptvanhanh.hcm.edu.vn | R9: =TINHKHOANGCACH(Ho_So_Hoc_Sinh!$B$3, C9) -> #NAME? | S9: =IF(ISBLANK(K9), 7, MIN(10, K9 * 4.5)) -> 7 | T9: =IF(L9="Có", 10, 6) -> 10 | U9: =Ho_So_Hoc_Sinh!$B$8 -> 10 | V9: =IF(ISBLANK(H9), 7.5, IF(Ho_So_Hoc_Sinh!$B$4>=H9+1, 10, IF(Ho_So_Hoc_Sinh!$B$4<H9-1, 0, 10 - 5*(H9+1-Ho_So_Hoc_Sinh!$B$4)))) -> 7.5 | W9: =IF(D9="Công lập", 10, 5) -> 5 | X9: =MAX(0, 10*(1 - R9/10)) -> #NAME? | Y9: =IF(Ho_So_Hoc_Sinh!$B$5=0, 10, IF(M9="Có", 10, 0)) -> 10 | Z9: =0.154*S9 + 0.152*T9 + 0.145*U9 + 0.144*V9 + 0.14*W9 + 0.138*X9 + 0.128*Y9 -> #NAME? | AA9: =IF(RANK(Z9, $Z$3:$Z$48)=1, "Top 1", IF(RANK(Z9, $Z$3:$Z$48)=2, "Top 2", IF(RANK(Z9, $Z$3:$Z$48)=3, "Top 3", "Khác"))) -> #NAME?
A10: 8 | B10: THPT Nguyễn Thị Minh Khai | C10: 275 Điện Biên Phủ, Phường Xuân Hòa, Tp. HCM | D10: Công lập | E10: Có | F10: 10.779171 | G10: 106.68679 | H10: 24.5 | I10: 23.83 | J10: 845 | K10: 1.97 | L10: Có | M10: Có | N10: 200000 | O10: 04, 10, 30, 54, 91, 150 | P10: Báo chí - Truyền thông '8:15', Hát Muzika, Nhiếp ảnh,... | Q10: https://thptnguyenthiminhkhai.hcm.edu.vn | R10: =TINHKHOANGCACH(Ho_So_Hoc_Sinh!$B$3, C10) -> #NAME? | S10: =IF(ISBLANK(K10), 7, MIN(10, K10 * 4.5)) -> 8.865 | T10: =IF(L10="Có", 10, 6) -> 10 | U10: =Ho_So_Hoc_Sinh!$B$8 -> 10 | V10: =IF(ISBLANK(H10), 7.5, IF(Ho_So_Hoc_Sinh!$B$4>=H10+1, 10, IF(Ho_So_Hoc_Sinh!$B$4<H10-1, 0, 10 - 5*(H10+1-Ho_So_Hoc_Sinh!$B$4)))) -> 0 | W10: =IF(D10="Công lập", 10, 5) -> 10 | X10: =MAX(0, 10*(1 - R10/10)) -> #NAME? | Y10: =IF(Ho_So_Hoc_Sinh!$B$5=0, 10, IF(M10="Có", 10, 0)) -> 10 | Z10: =0.154*S10 + 0.152*T10 + 0.145*U10 + 0.144*V10 + 0.14*W10 + 0.138*X10 + 0.128*Y10 -> #NAME? | AA10: =IF(RANK(Z10, $Z$3:$Z$48)=1, "Top 1", IF(RANK(Z10, $Z$3:$Z$48)=2, "Top 2", IF(RANK(Z10, $Z$3:$Z$48)=3, "Top 3", "Khác"))) -> #NAME?
A11: 9 | B11: THPT Marie Curie | C11: 159 Nam Kỳ Khởi Nghĩa, Phường Xuân Hòa, Tp. HCM | D11: Công lập | E11: Có | F11: 10.782565 | G11: 106.69119 | H11: 22.25 | I11: 20.5 | J11: 1000 | K11: 1.52 | L11: Có | M11: Có | N11: 200000 | O11: 04, 06, 10, 36, 93, 150 | P11: Truyền thông trẻ Mediarie, Nhiếp ảnh, Khoa học sáng tạo... | Q11: https://thptmariecurie.hcm.edu.vn | R11: =TINHKHOANGCACH(Ho_So_Hoc_Sinh!$B$3, C11) -> #NAME? | S11: =IF(ISBLANK(K11), 7, MIN(10, K11 * 4.5)) -> 6.84 | T11: =IF(L11="Có", 10, 6) -> 10 | U11: =Ho_So_Hoc_Sinh!$B$8 -> 10 | V11: =IF(ISBLANK(H11), 7.5, IF(Ho_So_Hoc_Sinh!$B$4>=H11+1, 10, IF(Ho_So_Hoc_Sinh!$B$4<H11-1, 0, 10 - 5*(H11+1-Ho_So_Hoc_Sinh!$B$4)))) -> 0 | W11: =IF(D11="Công lập", 10, 5) -> 10 | X11: =MAX(0, 10*(1 - R11/10)) -> #NAME? | Y11: =IF(Ho_So_Hoc_Sinh!$B$5=0, 10, IF(M11="Có", 10, 0)) -> 10 | Z11: =0.154*S11 + 0.152*T11 + 0.145*U11 + 0.144*V11 + 0.14*W11 + 0.138*X11 + 0.128*Y11 -> #NAME? | AA11: =IF(RANK(Z11, $Z$3:$Z$48)=1, "Top 1", IF(RANK(Z11, $Z$3:$Z$48)=2, "Top 2", IF(RANK(Z11, $Z$3:$Z$48)=3, "Top 3", "Khác"))) -> #NAME?
A12: 10 | B12: THPT Lê Quý Đôn | C12: 110 Nguyễn Thị Minh Khai, Phường Xuân Hòa, Tp. HCM | D12: Công lập | E12: Có | F12: 10.779269 | G12: 106.69451 | H12: 23.75 | I12: 22.83 | J12: 560 | K12: 2.31 | L12: Có | M12: Có | N12: 2000000 | O12: 04, 06, 30, 31, 93, 152 | P12: STEM, Tình nguyện - Kỹ năng sống, các CLB thể thao | Q12: https://www.thpt-lequydon-hcm.edu.vn/home.aspx | R12: =TINHKHOANGCACH(Ho_So_Hoc_Sinh!$B$3, C12) -> #NAME? | S12: =IF(ISBLANK(K12), 7, MIN(10, K12 * 4.5)) -> 10 | T12: =IF(L12="Có", 10, 6) -> 10 | U12: =Ho_So_Hoc_Sinh!$B$8 -> 10 | V12: =IF(ISBLANK(H12), 7.5, IF(Ho_So_Hoc_Sinh!$B$4>=H12+1, 10, IF(Ho_So_Hoc_Sinh!$B$4<H12-1, 0, 10 - 5*(H12+1-Ho_So_Hoc_Sinh!$B$4)))) -> 0 | W12: =IF(D12="Công lập", 10, 5) -> 10 | X12: =MAX(0, 10*(1 - R12/10)) -> #NAME? | Y12: =IF(Ho_So_Hoc_Sinh!$B$5=0, 10, IF(M12="Có", 10, 0)) -> 10 | Z12: =0.154*S12 + 0.152*T12 + 0.145*U12 + 0.144*V12 + 0.14*W12 + 0.138*X12 + 0.128*Y12 -> #NAME? | AA12: =IF(RANK(Z12, $Z$3:$Z$48)=1, "Top 1", IF(RANK(Z12, $Z$3:$Z$48)=2, "Top 2", IF(RANK(Z12, $Z$3:$Z$48)=3, "Top 3", "Khác"))) -> #NAME?
A13: 11 | B13: THPT Nguyễn Thị Diệu | C13: 12 Trần Quốc Toản, Phường Xuân Hòa, Tp. HCM | D13: Công lập | E13: Có | F13: 10.789354 | G13: 106.68919 | H13: 15.75 | I13: 13.83 | J13: 765 | K13: 0.38 | L13: Có | M13: Có | N13: 200000 | O13: 10, 28, 30, 91 | P13: Văn nghệ, Học thuật - Truyền Thông, các CLB thể thao,... | Q13: https://thptnguyenthidieu.hcm.edu.vn | R13: =TINHKHOANGCACH(Ho_So_Hoc_Sinh!$B$3, C13) -> #NAME? | S13: =IF(ISBLANK(K13), 7, MIN(10, K13 * 4.5)) -> 1.71 | T13: =IF(L13="Có", 10, 6) -> 10 | U13: =Ho_So_Hoc_Sinh!$B$8 -> 10 | V13: =IF(ISBLANK(H13), 7.5, IF(Ho_So_Hoc_Sinh!$B$4>=H13+1, 10, IF(Ho_So_Hoc_Sinh!$B$4<H13-1, 0, 10 - 5*(H13+1-Ho_So_Hoc_Sinh!$B$4)))) -> 10 | W13: =IF(D13="Công lập", 10, 5) -> 10 | X13: =MAX(0, 10*(1 - R13/10)) -> #NAME? | Y13: =IF(Ho_So_Hoc_Sinh!$B$5=0, 10, IF(M13="Có", 10, 0)) -> 10 | Z13: =0.154*S13 + 0.152*T13 + 0.145*U13 + 0.144*V13 + 0.14*W13 + 0.138*X13 + 0.128*Y13 -> #NAME? | AA13: =IF(RANK(Z13, $Z$3:$Z$48)=1, "Top 1", IF(RANK(Z13, $Z$3:$Z$48)=2, "Top 2", IF(RANK(Z13, $Z$3:$Z$48)=3, "Top 3", "Khác"))) -> #NAME?
A14: 12 | B14: Trung tâm GDKTTH và HN Lê Thị Hồng Gấm | C14: 147 Pasteur, Phường Xuân Hoà, Tp. HCM | D14: Công lập | E14: Có | F14: 10.784269 | G14: 106.6913 | H14: 14.25 | I14: 13.67 | J14: 495 | K14: 0.3 | L14: Có | M14: Có | N14: 200000 | O14: 04, 36, 91, 109, 150 | P14: Mỹ thuật, Nhảy, Truyền thống,... | Q14: https://thptlethihonggam.hcm.edu.vn/ | R14: =TINHKHOANGCACH(Ho_So_Hoc_Sinh!$B$3, C14) -> #NAME? | S14: =IF(ISBLANK(K14), 7, MIN(10, K14 * 4.5)) -> 1.35 | T14: =IF(L14="Có", 10, 6) -> 10 | U14: =Ho_So_Hoc_Sinh!$B$8 -> 10 | V14: =IF(ISBLANK(H14), 7.5, IF(Ho_So_Hoc_Sinh!$B$4>=H14+1, 10, IF(Ho_So_Hoc_Sinh!$B$4<H14-1, 0, 10 - 5*(H14+1-Ho_So_Hoc_Sinh!$B$4)))) -> 10 | W14: =IF(D14="Công lập", 10, 5) -> 10 | X14: =MAX(0, 10*(1 - R14/10)) -> #NAME? | Y14: =IF(Ho_So_Hoc_Sinh!$B$5=0, 10, IF(M14="Có", 10, 0)) -> 10 | Z14: =0.154*S14 + 0.152*T14 + 0.145*U14 + 0.144*V14 + 0.14*W14 + 0.138*X14 + 0.128*Y14 -> #NAME? | AA14: =IF(RANK(Z14, $Z$3:$Z$48)=1, "Top 1", IF(RANK(Z14, $Z$3:$Z$48)=2, "Top 2", IF(RANK(Z14, $Z$3:$Z$48)=3, "Top 3", "Khác"))) -> #NAME?
A15: 13 | B15: THPT Nam Kỳ Khởi Nghĩa | C15: 269/8 Nguyễn Thị Nhỏ, Phường Minh Phụng, Tp. HCM | D15: Công lập | E15: Có | F15: 10.757506 | G15: 106.65022 | H15: 16.5 | I15: 15.25 | J15: 765 | K15: 1.11 | L15: Có | M15: Có | N15: 200000 | O15: 08, 14, 38, 62, 69, 145 | P15: Văn nghệ, Học thuật - Truyền Thông, các CLB thể thao,... | Q15: https://thptnamkykhoinghia.hcm.edu.vn | R15: =TINHKHOANGCACH(Ho_So_Hoc_Sinh!$B$3, C15) -> #NAME? | S15: =IF(ISBLANK(K15), 7, MIN(10, K15 * 4.5)) -> 4.995 | T15: =IF(L15="Có", 10, 6) -> 10 | U15: =Ho_So_Hoc_Sinh!$B$8 -> 10 | V15: =IF(ISBLANK(H15), 7.5, IF(Ho_So_Hoc_Sinh!$B$4>=H15+1, 10, IF(Ho_So_Hoc_Sinh!$B$4<H15-1, 0, 10 - 5*(H15+1-Ho_So_Hoc_Sinh!$B$4)))) -> 10 | W15: =IF(D15="Công lập", 10, 5) -> 10 | X15: =MAX(0, 10*(1 - R15/10)) -> #NAME? | Y15: =IF(Ho_So_Hoc_Sinh!$B$5=0, 10, IF(M15="Có", 10, 0)) -> 10 | Z15: =0.154*S15 + 0.152*T15 + 0.145*U15 + 0.144*V15 + 0.14*W15 + 0.138*X15 + 0.128*Y15 -> #NAME? | AA15: =IF(RANK(Z15, $Z$3:$Z$48)=1, "Top 1", IF(RANK(Z15, $Z$3:$Z$48)=2, "Top 2", IF(RANK(Z15, $Z$3:$Z$48)=3, "Top 3", "Khác"))) -> #NAME?
A16: 14 | B16: THPT Nguyễn Hiền | C16: 3 Dương Đình Nghệ, Phường Bình Thới, Tp. HCM | D16: Công lập | E16: Có | F16: 10.761427 | G16: 106.65021 | H16: 19.75 | I16: 18.58 | J16: 595 | K16: 1.24 | L16: Có | M16: Có | N16: 1700000 | O16: 59, 103, 145, 148 | P16: Gym học đường, Karate, các CLB thể thao,... | Q16: https://thptnguyenhien.hcm.edu.vn | R16: =TINHKHOANGCACH(Ho_So_Hoc_Sinh!$B$3, C16) -> #NAME? | S16: =IF(ISBLANK(K16), 7, MIN(10, K16 * 4.5)) -> 5.58 | T16: =IF(L16="Có", 10, 6) -> 10 | U16: =Ho_So_Hoc_Sinh!$B$8 -> 10 | V16: =IF(ISBLANK(H16), 7.5, IF(Ho_So_Hoc_Sinh!$B$4>=H16+1, 10, IF(Ho_So_Hoc_Sinh!$B$4<H16-1, 0, 10 - 5*(H16+1-Ho_So_Hoc_Sinh!$B$4)))) -> 10 | W16: =IF(D16="Công lập", 10, 5) -> 10 | X16: =MAX(0, 10*(1 - R16/10)) -> #NAME? | Y16: =IF(Ho_So_Hoc_Sinh!$B$5=0, 10, IF(M16="Có", 10, 0)) -> 10 | Z16: =0.154*S16 + 0.152*T16 + 0.145*U16 + 0.144*V16 + 0.14*W16 + 0.138*X16 + 0.128*Y16 -> #NAME? | AA16: =IF(RANK(Z16, $Z$3:$Z$48)=1, "Top 1", IF(RANK(Z16, $Z$3:$Z$48)=2, "Top 2", IF(RANK(Z16, $Z$3:$Z$48)=3, "Top 3", "Khác"))) -> #NAME?
A17: 15 | B17: THPT Trần Quốc Tuấn | C17: 236/10-12 Thái Phiên, Phường Bình Thới, Tp. HCM | D17: Tư thục | E17: Có | F17: 10.761208 | G17: 106.64715 | L17: Có | M17: Có | N17: 3200000 | O17: 05, 10, 27, 38, 50, 69, 103, 148, 150 | P17: Văn nghệ, Học thuật - Truyền Thông, các CLB thể thao,... | Q17: https://thpttranquoctuan.edu.vn/ | R17: =TINHKHOANGCACH(Ho_So_Hoc_Sinh!$B$3, C17) -> #NAME? | S17: =IF(ISBLANK(K17), 7, MIN(10, K17 * 4.5)) -> 7 | T17: =IF(L17="Có", 10, 6) -> 10 | U17: =Ho_So_Hoc_Sinh!$B$8 -> 10 | V17: =IF(ISBLANK(H17), 7.5, IF(Ho_So_Hoc_Sinh!$B$4>=H17+1, 10, IF(Ho_So_Hoc_Sinh!$B$4<H17-1, 0, 10 - 5*(H17+1-Ho_So_Hoc_Sinh!$B$4)))) -> 7.5 | W17: =IF(D17="Công lập", 10, 5) -> 5 | X17: =MAX(0, 10*(1 - R17/10)) -> #NAME? | Y17: =IF(Ho_So_Hoc_Sinh!$B$5=0, 10, IF(M17="Có", 10, 0)) -> 10 | Z17: =0.154*S17 + 0.152*T17 + 0.145*U17 + 0.144*V17 + 0.14*W17 + 0.138*X17 + 0.128*Y17 -> #NAME? | AA17: =IF(RANK(Z17, $Z$3:$Z$48)=1, "Top 1", IF(RANK(Z17, $Z$3:$Z$48)=2, "Top 2", IF(RANK(Z17, $Z$3:$Z$48)=3, "Top 3", "Khác"))) -> #NAME?
A18: 16 | B18: THPT Trần Quang Khải | C18: 343D Lạc Long Quân, Phường Hoà Bình, Tp. HCM | D18: Công lập | E18: Có | F18: 10.769944 | G18: 106.64257 | H18: 17.75 | I18: 16.83 | J18: 990 | K18: 1.04 | L18: Có | M18: Có | N18: 200000 | O18: 05, 10, 27, 38, 50, 69, 103, 148, 150 | P18: Văn nghệ, Học thuật - Truyền Thông, các CLB thể thao,... | Q18: https://thpttranquangkhai.hcm.edu.vn/ | R18: =TINHKHOANGCACH(Ho_So_Hoc_Sinh!$B$3, C18) -> #NAME? | S18: =IF(ISBLANK(K18), 7, MIN(10, K18 * 4.5)) -> 4.68 | T18: =IF(L18="Có", 10, 6) -> 10 | U18: =Ho_So_Hoc_Sinh!$B$8 -> 10 | V18: =IF(ISBLANK(H18), 7.5, IF(Ho_So_Hoc_Sinh!$B$4>=H18+1, 10, IF(Ho_So_Hoc_Sinh!$B$4<H18-1, 0, 10 - 5*(H18+1-Ho_So_Hoc_Sinh!$B$4)))) -> 10 | W18: =IF(D18="Công lập", 10, 5) -> 10 | X18: =MAX(0, 10*(1 - R18/10)) -> #NAME? | Y18: =IF(Ho_So_Hoc_Sinh!$B$5=0, 10, IF(M18="Có", 10, 0)) -> 10 | Z18: =0.154*S18 + 0.152*T18 + 0.145*U18 + 0.144*V18 + 0.14*W18 + 0.138*X18 + 0.128*Y18 -> #NAME? | AA18: =IF(RANK(Z18, $Z$3:$Z$48)=1, "Top 1", IF(RANK(Z18, $Z$3:$Z$48)=2, "Top 2", IF(RANK(Z18, $Z$3:$Z$48)=3, "Top 3", "Khác"))) -> #NAME?
A19: 17 | B19: Trung học Thực hành Đại học Sư phạm | C19: 280 An Dương Vương, Phường Chợ Quán, Tp. HCM | D19: Công lập | E19: Có | F19: 10.762793 | G19: 106.68091 | H19: 24.5 | I19: 23.5 | J19: 280 | K19: 2.31 | L19: Có | M19: Có | N19: 1800000 | O19: 06, 11, 38, 45, 56, 139 | P19: Văn nghệ, Học thuật - Truyền Thông, các CLB thể thao,... | Q19: http://trunghocthuchanh.hcmue.edu.vn/ | R19: =TINHKHOANGCACH(Ho_So_Hoc_Sinh!$B$3, C19) -> #NAME? | S19: =IF(ISBLANK(K19), 7, MIN(10, K19 * 4.5)) -> 10 | T19: =IF(L19="Có", 10, 6) -> 10 | U19: =Ho_So_Hoc_Sinh!$B$8 -> 10 | V19: =IF(ISBLANK(H19), 7.5, IF(Ho_So_Hoc_Sinh!$B$4>=H19+1, 10, IF(Ho_So_Hoc_Sinh!$B$4<H19-1, 0, 10 - 5*(H19+1-Ho_So_Hoc_Sinh!$B$4)))) -> 0 | W19: =IF(D19="Công lập", 10, 5) -> 10 | X19: =MAX(0, 10*(1 - R19/10)) -> #NAME? | Y19: =IF(Ho_So_Hoc_Sinh!$B$5=0, 10, IF(M19="Có", 10, 0)) -> 10 | Z19: =0.154*S19 + 0.152*T19 + 0.145*U19 + 0.144*V19 + 0.14*W19 + 0.138*X19 + 0.128*Y19 -> #NAME? | AA19: =IF(RANK(Z19, $Z$3:$Z$48)=1, "Top 1", IF(RANK(Z19, $Z$3:$Z$48)=2, "Top 2", IF(RANK(Z19, $Z$3:$Z$48)=3, "Top 3", "Khác"))) -> #NAME?
A20: 18 | B20: Trung học Thực hành Sài Gòn | C20: 220 Trần Bình Phong, Phường Chợ Quán, Tp. HCM | D20: Công lập | E20: Có | F20: 10.76098 | G20: 106.67986 | H20: 23.5 | I20: 22 | J20: 175 | K20: 2 | L20: Có | M20: Có | N20: 200000 | O20: 05, 27, 45, 56, 68, 91 | P20: Lịch sử - Văn hoá, The Music Box, Lửa Thanh Xuân,... | Q20: https://thuchanhsaigon.sgu.edu.vn/ | R20: =TINHKHOANGCACH(Ho_So_Hoc_Sinh!$B$3, C20) -> #NAME? | S20: =IF(ISBLANK(K20), 7, MIN(10, K20 * 4.5)) -> 9 | T20: =IF(L20="Có", 10, 6) -> 10 | U20: =Ho_So_Hoc_Sinh!$B$8 -> 10 | V20: =IF(ISBLANK(H20), 7.5, IF(Ho_So_Hoc_Sinh!$B$4>=H20+1, 10, IF(Ho_So_Hoc_Sinh!$B$4<H20-1, 0, 10 - 5*(H20+1-Ho_So_Hoc_Sinh!$B$4)))) -> 0 | W20: =IF(D20="Công lập", 10, 5) -> 10 | X20: =MAX(0, 10*(1 - R20/10)) -> #NAME? | Y20: =IF(Ho_So_Hoc_Sinh!$B$5=0, 10, IF(M20="Có", 10, 0)) -> 10 | Z20: =0.154*S20 + 0.152*T20 + 0.145*U20 + 0.144*V20 + 0.14*W20 + 0.138*X20 + 0.128*Y20 -> #NAME? | AA20: =IF(RANK(Z20, $Z$3:$Z$48)=1, "Top 1", IF(RANK(Z20, $Z$3:$Z$48)=2, "Top 2", IF(RANK(Z20, $Z$3:$Z$48)=3, "Top 3", "Khác"))) -> #NAME?
A21: 19 | B21: THPT Hùng Vương | C21: 124 Hồng Bàng, Phường Chợ Lớn, Tp. HCM | D21: Công lập | E21: Có | F21: 10.755986 | G21: 106.66371 | H21: 21 | I21: 19 | J21: 1035 | K21: 1.66 | L21: Có | M21: Có | N21: 200000 | O21: 05, 06, 08, 09, 56, 139, 150 | P21: Văn nghệ, Học thuật - Truyền Thông, các CLB thể thao,... | Q21: https://thpthungvuong.hcm.edu.vn | R21: =TINHKHOANGCACH(Ho_So_Hoc_Sinh!$B$3, C21) -> #NAME? | S21: =IF(ISBLANK(K21), 7, MIN(10, K21 * 4.5)) -> 7.47 | T21: =IF(L21="Có", 10, 6) -> 10 | U21: =Ho_So_Hoc_Sinh!$B$8 -> 10 | V21: =IF(ISBLANK(H21), 7.5, IF(Ho_So_Hoc_Sinh!$B$4>=H21+1, 10, IF(Ho_So_Hoc_Sinh!$B$4<H21-1, 0, 10 - 5*(H21+1-Ho_So_Hoc_Sinh!$B$4)))) -> 5 | W21: =IF(D21="Công lập", 10, 5) -> 10 | X21: =MAX(0, 10*(1 - R21/10)) -> #NAME? | Y21: =IF(Ho_So_Hoc_Sinh!$B$5=0, 10, IF(M21="Có", 10, 0)) -> 10 | Z21: =0.154*S21 + 0.152*T21 + 0.145*U21 + 0.144*V21 + 0.14*W21 + 0.138*X21 + 0.128*Y21 -> #NAME? | AA21: =IF(RANK(Z21, $Z$3:$Z$48)=1, "Top 1", IF(RANK(Z21, $Z$3:$Z$48)=2, "Top 2", IF(RANK(Z21, $Z$3:$Z$48)=3, "Top 3", "Khác"))) -> #NAME?
A22: 20 | B22: THPT Trần Khai Nguyên | C22: 225 Nguyễn Tri Phương, Phường An Đông, Tp. HCM | D22: Công lập | E22: Có | F22: 10.75787 | G22: 106.66889 | H22: 23 | I22: 21.25 | J22: 720 | K22: 2.02 | L22: Có | M22: Có | N22: 200000 | O22: 05, 10, 14, 56, 91, 139 | P22: Văn nghệ, Học thuật - Truyền Thông, các CLB thể thao,... | Q22: https://thpttrankhainguyen.hcm.edu.vn | R22: =TINHKHOANGCACH(Ho_So_Hoc_Sinh!$B$3, C22) -> #NAME? | S22: =IF(ISBLANK(K22), 7, MIN(10, K22 * 4.5)) -> 9.09 | T22: =IF(L22="Có", 10, 6) -> 10 | U22: =Ho_So_Hoc_Sinh!$B$8 -> 10 | V22: =IF(ISBLANK(H22), 7.5, IF(Ho_So_Hoc_Sinh!$B$4>=H22+1, 10, IF(Ho_So_Hoc_Sinh!$B$4<H22-1, 0, 10 - 5*(H22+1-Ho_So_Hoc_Sinh!$B$4)))) -> 0 | W22: =IF(D22="Công lập", 10, 5) -> 10 | X22: =MAX(0, 10*(1 - R22/10)) -> #NAME? | Y22: =IF(Ho_So_Hoc_Sinh!$B$5=0, 10, IF(M22="Có", 10, 0)) -> 10 | Z22: =0.154*S22 + 0.152*T22 + 0.145*U22 + 0.144*V22 + 0.14*W22 + 0.138*X22 + 0.128*Y22 -> #NAME? | AA22: =IF(RANK(Z22, $Z$3:$Z$48)=1, "Top 1", IF(RANK(Z22, $Z$3:$Z$48)=2, "Top 2", IF(RANK(Z22, $Z$3:$Z$48)=3, "Top 3", "Khác"))) -> #NAME?
A23: 21 | B23: THPT Nguyễn Trãi | C23: 364 Nguyễn Tất Thành, Phường Xóm Chiếu, Tp. HCM | D23: Công lập | E23: Có | F23: 10.759712 | G23: 106.71208 | H23: 15.25 | I23: 13.42 | J23: 675 | K23: 0.62 | L23: Có | M23: Có | N23: 200000 | O23: 01, 06, 56, 139 | P23: Văn nghệ, Học thuật - Truyền Thông, các CLB thể thao,... | Q23: https://thptnguyentrai.hcm.edu.vn | R23: =TINHKHOANGCACH(Ho_So_Hoc_Sinh!$B$3, C23) -> #NAME? | S23: =IF(ISBLANK(K23), 7, MIN(10, K23 * 4.5)) -> 2.79 | T23: =IF(L23="Có", 10, 6) -> 10 | U23: =Ho_So_Hoc_Sinh!$B$8 -> 10 | V23: =IF(ISBLANK(H23), 7.5, IF(Ho_So_Hoc_Sinh!$B$4>=H23+1, 10, IF(Ho_So_Hoc_Sinh!$B$4<H23-1, 0, 10 - 5*(H23+1-Ho_So_Hoc_Sinh!$B$4)))) -> 10 | W23: =IF(D23="Công lập", 10, 5) -> 10 | X23: =MAX(0, 10*(1 - R23/10)) -> #NAME? | Y23: =IF(Ho_So_Hoc_Sinh!$B$5=0, 10, IF(M23="Có", 10, 0)) -> 10 | Z23: =0.154*S23 + 0.152*T23 + 0.145*U23 + 0.144*V23 + 0.14*W23 + 0.138*X23 + 0.128*Y23 -> #NAME? | AA23: =IF(RANK(Z23, $Z$3:$Z$48)=1, "Top 1", IF(RANK(Z23, $Z$3:$Z$48)=2, "Top 2", IF(RANK(Z23, $Z$3:$Z$48)=3, "Top 3", "Khác"))) -> #NAME?
A24: 22 | B24: THPT Trần Hữu Trang | C24: 276 Trần Hưng Đạo B, Phường Chợ Lớn, Tp. HCM | D24: Công lập | E24: Có | F24: 10.752478 | G24: 106.66319 | H24: 14 | I24: 13.42 | J24: 540 | K24: 0.29 | L24: Có | M24: Có | N24: 200000 | O24: 01, 39, 56, 62, 63-1 | P24: Văn nghệ, Học thuật - Truyền Thông, các CLB thể thao,... | Q24: https://thpttranhuutrang.hcm.edu.vn | R24: =TINHKHOANGCACH(Ho_So_Hoc_Sinh!$B$3, C24) -> #NAME? | S24: =IF(ISBLANK(K24), 7, MIN(10, K24 * 4.5)) -> 1.305 | T24: =IF(L24="Có", 10, 6) -> 10 | U24: =Ho_So_Hoc_Sinh!$B$8 -> 10 | V24: =IF(ISBLANK(H24), 7.5, IF(Ho_So_Hoc_Sinh!$B$4>=H24+1, 10, IF(Ho_So_Hoc_Sinh!$B$4<H24-1, 0, 10 - 5*(H24+1-Ho_So_Hoc_Sinh!$B$4)))) -> 10 | W24: =IF(D24="Công lập", 10, 5) -> 10 | X24: =MAX(0, 10*(1 - R24/10)) -> #NAME? | Y24: =IF(Ho_So_Hoc_Sinh!$B$5=0, 10, IF(M24="Có", 10, 0)) -> 10 | Z24: =0.154*S24 + 0.152*T24 + 0.145*U24 + 0.144*V24 + 0.14*W24 + 0.138*X24 + 0.128*Y24 -> #NAME? | AA24: =IF(RANK(Z24, $Z$3:$Z$48)=1, "Top 1", IF(RANK(Z24, $Z$3:$Z$48)=2, "Top 2", IF(RANK(Z24, $Z$3:$Z$48)=3, "Top 3", "Khác"))) -> #NAME?
A25: 23 | B25: THPT Nguyễn Thượng Hiền | C25: 544 Cách Mạng Tháng 8, Phường Tân Sân Nhất, Tp. HCM | D25: Công lập | E25: Có | F25: 10.793517 | G25: 106.65475 | H25: 24.75 | I25: 24.17 | J25: 780 | K25: 2.51 | L25: Có | M25: Có | N25: 200000 | O25: 08, 13, 30, 65, 103, 148 | P25: Tranh biện (Phoenix), Nhảy hiện đại (LCD Crewz),... | Q25: https://thptnguyenthuonghien.hcm.edu.vn | R25: =TINHKHOANGCACH(Ho_So_Hoc_Sinh!$B$3, C25) -> #NAME? | S25: =IF(ISBLANK(K25), 7, MIN(10, K25 * 4.5)) -> 10 | T25: =IF(L25="Có", 10, 6) -> 10 | U25: =Ho_So_Hoc_Sinh!$B$8 -> 10 | V25: =IF(ISBLANK(H25), 7.5, IF(Ho_So_Hoc_Sinh!$B$4>=H25+1, 10, IF(Ho_So_Hoc_Sinh!$B$4<H25-1, 0, 10 - 5*(H25+1-Ho_So_Hoc_Sinh!$B$4)))) -> 0 | W25: =IF(D25="Công lập", 10, 5) -> 10 | X25: =MAX(0, 10*(1 - R25/10)) -> #NAME? | Y25: =IF(Ho_So_Hoc_Sinh!$B$5=0, 10, IF(M25="Có", 10, 0)) -> 10 | Z25: =0.154*S25 + 0.152*T25 + 0.145*U25 + 0.144*V25 + 0.14*W25 + 0.138*X25 + 0.128*Y25 -> #NAME? | AA25: =IF(RANK(Z25, $Z$3:$Z$48)=1, "Top 1", IF(RANK(Z25, $Z$3:$Z$48)=2, "Top 2", IF(RANK(Z25, $Z$3:$Z$48)=3, "Top 3", "Khác"))) -> #NAME?
A26: 24 | B26: THPT Tân Bình | C26: 19 Nguyễn Thái Bình, Phường Tân Sơn Nhất, Tp. HCM | D26: Công lập | E26: Có | F26: 10.79874 | G26: 106.62825 | H26: 21.5 | I26: 20.25 | J26: 855 | K26: 1.19 | L26: Có | M26: Có | N26: 200000 | O26: 04, 28, 65, 104, 152 | P26: Văn nghệ, Học thuật - Truyền Thông, các CLB thể thao,... | Q26: https://thpttanbinh.hcm.edu.vn | R26: =TINHKHOANGCACH(Ho_So_Hoc_Sinh!$B$3, C26) -> #NAME? | S26: =IF(ISBLANK(K26), 7, MIN(10, K26 * 4.5)) -> 5.355 | T26: =IF(L26="Có", 10, 6) -> 10 | U26: =Ho_So_Hoc_Sinh!$B$8 -> 10 | V26: =IF(ISBLANK(H26), 7.5, IF(Ho_So_Hoc_Sinh!$B$4>=H26+1, 10, IF(Ho_So_Hoc_Sinh!$B$4<H26-1, 0, 10 - 5*(H26+1-Ho_So_Hoc_Sinh!$B$4)))) -> 2.5 | W26: =IF(D26="Công lập", 10, 5) -> 10 | X26: =MAX(0, 10*(1 - R26/10)) -> #NAME? | Y26: =IF(Ho_So_Hoc_Sinh!$B$5=0, 10, IF(M26="Có", 10, 0)) -> 10 | Z26: =0.154*S26 + 0.152*T26 + 0.145*U26 + 0.144*V26 + 0.14*W26 + 0.138*X26 + 0.128*Y26 -> #NAME? | AA26: =IF(RANK(Z26, $Z$3:$Z$48)=1, "Top 1", IF(RANK(Z26, $Z$3:$Z$48)=2, "Top 2", IF(RANK(Z26, $Z$3:$Z$48)=3, "Top 3", "Khác"))) -> #NAME?
A27: 25 | B27: THPT Nguyễn Chí Thanh | C27: 1A Hoàng Hoa Thám, Phường Tân Sơn Nhất, Tp. HCM | D27: Công lập | E27: Có | F27: 10.8063 | G27: 106.64611 | H27: 20.25 | I27: 18.83 | J27: 810 | K27: 1.03 | L27: Có | M27: Có | N27: 200000 | O27: 04, 13, 18, 30, 65, 145 | P27: Văn nghệ, Học thuật - Truyền Thông, các CLB thể thao,... | Q27: https://thptnguyenchithanh.hcm.edu.vn | R27: =TINHKHOANGCACH(Ho_So_Hoc_Sinh!$B$3, C27) -> #NAME? | S27: =IF(ISBLANK(K27), 7, MIN(10, K27 * 4.5)) -> 4.635 | T27: =IF(L27="Có", 10, 6) -> 10 | U27: =Ho_So_Hoc_Sinh!$B$8 -> 10 | V27: =IF(ISBLANK(H27), 7.5, IF(Ho_So_Hoc_Sinh!$B$4>=H27+1, 10, IF(Ho_So_Hoc_Sinh!$B$4<H27-1, 0, 10 - 5*(H27+1-Ho_So_Hoc_Sinh!$B$4)))) -> 8.75 | W27: =IF(D27="Công lập", 10, 5) -> 10 | X27: =MAX(0, 10*(1 - R27/10)) -> #NAME? | Y27: =IF(Ho_So_Hoc_Sinh!$B$5=0, 10, IF(M27="Có", 10, 0)) -> 10 | Z27: =0.154*S27 + 0.152*T27 + 0.145*U27 + 0.144*V27 + 0.14*W27 + 0.138*X27 + 0.128*Y27 -> #NAME? | AA27: =IF(RANK(Z27, $Z$3:$Z$48)=1, "Top 1", IF(RANK(Z27, $Z$3:$Z$48)=2, "Top 2", IF(RANK(Z27, $Z$3:$Z$48)=3, "Top 3", "Khác"))) -> #NAME?
A28: 26 | B28: THPT Hoàng Hoa Thám | C28: 6 Hoàng Hoa Thám, Phường Tân Sơn Nhất, Tp. HCM | D28: Công lập | E28: Có | F28: 10.804181 | G28: 106.6928 | H28: 20.75 | I28: 18.58 | J28: 855 | K28: 1.58 | L28: Có | M28: Có | N28: 200000 | O28: 08, 24, 64, 104 | P28: Văn nghệ, Học thuật - Truyền Thông, các CLB thể thao,... | Q28: https://thpthoanghoatham.hcm.edu.vn | R28: =TINHKHOANGCACH(Ho_So_Hoc_Sinh!$B$3, C28) -> #NAME? | S28: =IF(ISBLANK(K28), 7, MIN(10, K28 * 4.5)) -> 7.11 | T28: =IF(L28="Có", 10, 6) -> 10 | U28: =Ho_So_Hoc_Sinh!$B$8 -> 10 | V28: =IF(ISBLANK(H28), 7.5, IF(Ho_So_Hoc_Sinh!$B$4>=H28+1, 10, IF(Ho_So_Hoc_Sinh!$B$4<H28-1, 0, 10 - 5*(H28+1-Ho_So_Hoc_Sinh!$B$4)))) -> 6.25 | W28: =IF(D28="Công lập", 10, 5) -> 10 | X28: =MAX(0, 10*(1 - R28/10)) -> #NAME? | Y28: =IF(Ho_So_Hoc_Sinh!$B$5=0, 10, IF(M28="Có", 10, 0)) -> 10 | Z28: =0.154*S28 + 0.152*T28 + 0.145*U28 + 0.144*V28 + 0.14*W28 + 0.138*X28 + 0.128*Y28 -> #NAME? | AA28: =IF(RANK(Z28, $Z$3:$Z$48)=1, "Top 1", IF(RANK(Z28, $Z$3:$Z$48)=2, "Top 2", IF(RANK(Z28, $Z$3:$Z$48)=3, "Top 3", "Khác"))) -> #NAME?
A29: 27 | B29: THPT Trương Vĩnh Ký | C29: 110 Bành Văn Trân, Phường Tân Sơn Nhất, Tp. HCM | D29: Tư thục | E29: Có | F29: 10.774977 | G29: 106.64631 | L29: Có | M29: Có | N29: 3600000 | O29: 05, 10, 27, 38, 50, 69, 103, 148, 150 | P29: Em yêu khoa học, Borussia Dortmund, các CLB thể thao,... | Q29: https://truongvinhky.edu.vn/ | R29: =TINHKHOANGCACH(Ho_So_Hoc_Sinh!$B$3, C29) -> #NAME? | S29: =IF(ISBLANK(K29), 7, MIN(10, K29 * 4.5)) -> 7 | T29: =IF(L29="Có", 10, 6) -> 10 | U29: =Ho_So_Hoc_Sinh!$B$8 -> 10 | V29: =IF(ISBLANK(H29), 7.5, IF(Ho_So_Hoc_Sinh!$B$4>=H29+1, 10, IF(Ho_So_Hoc_Sinh!$B$4<H29-1, 0, 10 - 5*(H29+1-Ho_So_Hoc_Sinh!$B$4)))) -> 7.5 | W29: =IF(D29="Công lập", 10, 5) -> 5 | X29: =MAX(0, 10*(1 - R29/10)) -> #NAME? | Y29: =IF(Ho_So_Hoc_Sinh!$B$5=0, 10, IF(M29="Có", 10, 0)) -> 10 | Z29: =0.154*S29 + 0.152*T29 + 0.145*U29 + 0.144*V29 + 0.14*W29 + 0.138*X29 + 0.128*Y29 -> #NAME? | AA29: =IF(RANK(Z29, $Z$3:$Z$48)=1, "Top 1", IF(RANK(Z29, $Z$3:$Z$48)=2, "Top 2", IF(RANK(Z29, $Z$3:$Z$48)=3, "Top 3", "Khác"))) -> #NAME?
A30: 28 | B30: THPT Nguyễn Thái Bình | C30: 913-915 Lý Thường Kiệt, Phường Tân Hoà, Tp. HCM | D30: Công lập | E30: Có | F30: 10.780029 | G30: 106.65523 | H30: 18.75 | I30: 17.33 | J30: 720 | K30: 1.22 | L30: Có | M30: Có | N30: 200000 | O30: 08, 38, 59, 63-1, 94, 103 | P30: Văn nghệ, Học thuật - Truyền Thông, các CLB thể thao,... | Q30: https://thptnguyenthaibinh.hcm.edu.vn | R30: =TINHKHOANGCACH(Ho_So_Hoc_Sinh!$B$3, C30) -> #NAME? | S30: =IF(ISBLANK(K30), 7, MIN(10, K30 * 4.5)) -> 5.49 | T30: =IF(L30="Có", 10, 6) -> 10 | U30: =Ho_So_Hoc_Sinh!$B$8 -> 10 | V30: =IF(ISBLANK(H30), 7.5, IF(Ho_So_Hoc_Sinh!$B$4>=H30+1, 10, IF(Ho_So_Hoc_Sinh!$B$4<H30-1, 0, 10 - 5*(H30+1-Ho_So_Hoc_Sinh!$B$4)))) -> 10 | W30: =IF(D30="Công lập", 10, 5) -> 10 | X30: =MAX(0, 10*(1 - R30/10)) -> #NAME? | Y30: =IF(Ho_So_Hoc_Sinh!$B$5=0, 10, IF(M30="Có", 10, 0)) -> 10 | Z30: =0.154*S30 + 0.152*T30 + 0.145*U30 + 0.144*V30 + 0.14*W30 + 0.138*X30 + 0.128*Y30 -> #NAME? | AA30: =IF(RANK(Z30, $Z$3:$Z$48)=1, "Top 1", IF(RANK(Z30, $Z$3:$Z$48)=2, "Top 2", IF(RANK(Z30, $Z$3:$Z$48)=3, "Top 3", "Khác"))) -> #NAME?
A31: 29 | B31: THPT Bùi Thị Xuân | C31: 73 Bùi Thị Xuân, Phường Bến Thành, Tp. HCM | D31: Công lập | E31: Có | F31: 10.769159 | G31: 106.68784 | H31: 24.25 | I31: 22.92 | J31: 700 | K31: 2.84 | L31: Có | M31: Có | N31: 200000 | O31: 13, 28, 36, 93, 140 | P31: Trí tuệ nhân tạo (AI - BTX), Văn nghệ Sắc màu,... | Q31: https://thptbuithixuan.hcm.edu.vn | R31: =TINHKHOANGCACH(Ho_So_Hoc_Sinh!$B$3, C31) -> #NAME? | S31: =IF(ISBLANK(K31), 7, MIN(10, K31 * 4.5)) -> 10 | T31: =IF(L31="Có", 10, 6) -> 10 | U31: =Ho_So_Hoc_Sinh!$B$8 -> 10 | V31: =IF(ISBLANK(H31), 7.5, IF(Ho_So_Hoc_Sinh!$B$4>=H31+1, 10, IF(Ho_So_Hoc_Sinh!$B$4<H31-1, 0, 10 - 5*(H31+1-Ho_So_Hoc_Sinh!$B$4)))) -> 0 | W31: =IF(D31="Công lập", 10, 5) -> 10 | X31: =MAX(0, 10*(1 - R31/10)) -> #NAME? | Y31: =IF(Ho_So_Hoc_Sinh!$B$5=0, 10, IF(M31="Có", 10, 0)) -> 10 | Z31: =0.154*S31 + 0.152*T31 + 0.145*U31 + 0.144*V31 + 0.14*W31 + 0.138*X31 + 0.128*Y31 -> #NAME? | AA31: =IF(RANK(Z31, $Z$3:$Z$48)=1, "Top 1", IF(RANK(Z31, $Z$3:$Z$48)=2, "Top 2", IF(RANK(Z31, $Z$3:$Z$48)=3, "Top 3", "Khác"))) -> #NAME?
A32: 30 | B32: THPT Ernst Thälmann (Ten Lơ Man) | C32: 8 Trần Hưng Đạo, Phường Bến Thành, Tp. HCM | D32: Công lập | E32: Có | F32: 10.768906 | G32: 106.69557 | H32: 20.5 | I32: 18.92 | J32: 585 | K32: 1.34 | L32: Có | M32: Có | N32: 200000 | O32: 01, 04, 18, 31, 36, 39, 45, 93, 152 | P32: Văn nghệ, Học thuật - Truyền Thông, các CLB thể thao,... | Q32: https://thpttenloman.hcm.edu.vn | R32: =TINHKHOANGCACH(Ho_So_Hoc_Sinh!$B$3, C32) -> #NAME? | S32: =IF(ISBLANK(K32), 7, MIN(10, K32 * 4.5)) -> 6.03 | T32: =IF(L32="Có", 10, 6) -> 10 | U32: =Ho_So_Hoc_Sinh!$B$8 -> 10 | V32: =IF(ISBLANK(H32), 7.5, IF(Ho_So_Hoc_Sinh!$B$4>=H32+1, 10, IF(Ho_So_Hoc_Sinh!$B$4<H32-1, 0, 10 - 5*(H32+1-Ho_So_Hoc_Sinh!$B$4)))) -> 7.5 | W32: =IF(D32="Công lập", 10, 5) -> 10 | X32: =MAX(0, 10*(1 - R32/10)) -> #NAME? | Y32: =IF(Ho_So_Hoc_Sinh!$B$5=0, 10, IF(M32="Có", 10, 0)) -> 10 | Z32: =0.154*S32 + 0.152*T32 + 0.145*U32 + 0.144*V32 + 0.14*W32 + 0.138*X32 + 0.128*Y32 -> #NAME? | AA32: =IF(RANK(Z32, $Z$3:$Z$48)=1, "Top 1", IF(RANK(Z32, $Z$3:$Z$48)=2, "Top 2", IF(RANK(Z32, $Z$3:$Z$48)=3, "Top 3", "Khác"))) -> #NAME?
A33: 31 | B33: THPT Lương Thế Vinh | C33: 131 Cô Bắc, Phường Cầu Ông Lãnh, Tp. HCM | D33: Công lập | E33: Có | F33: 10.763086 | G33: 106.6939 | H33: 22.75 | I33: 21.33 | J33: 330 | K33: 2.24 | L33: Có | M33: Có | N33: 200000 | O33: 18, 36, 45, 139, 140 | P33: Văn nghệ, Học thuật - Truyền Thông, các CLB thể thao,... | Q33: https://thptluongthevinh.hcm.edu.vn | R33: =TINHKHOANGCACH(Ho_So_Hoc_Sinh!$B$3, C33) -> #NAME? | S33: =IF(ISBLANK(K33), 7, MIN(10, K33 * 4.5)) -> 10 | T33: =IF(L33="Có", 10, 6) -> 10 | U33: =Ho_So_Hoc_Sinh!$B$8 -> 10 | V33: =IF(ISBLANK(H33), 7.5, IF(Ho_So_Hoc_Sinh!$B$4>=H33+1, 10, IF(Ho_So_Hoc_Sinh!$B$4<H33-1, 0, 10 - 5*(H33+1-Ho_So_Hoc_Sinh!$B$4)))) -> 0 | W33: =IF(D33="Công lập", 10, 5) -> 10 | X33: =MAX(0, 10*(1 - R33/10)) -> #NAME? | Y33: =IF(Ho_So_Hoc_Sinh!$B$5=0, 10, IF(M33="Có", 10, 0)) -> 10 | Z33: =0.154*S33 + 0.152*T33 + 0.145*U33 + 0.144*V33 + 0.14*W33 + 0.138*X33 + 0.128*Y33 -> #NAME? | AA33: =IF(RANK(Z33, $Z$3:$Z$48)=1, "Top 1", IF(RANK(Z33, $Z$3:$Z$48)=2, "Top 2", IF(RANK(Z33, $Z$3:$Z$48)=3, "Top 3", "Khác"))) -> #NAME?
A34: 32 | B34: THPT Trưng Vương | C34: 3 Nguyễn Bỉnh Khiêm, Phường Sài Gòn, Tp. HCM | D34: Công lập | E34: Có | F34: 10.785427 | G34: 106.70669 | H34: 21.75 | I34: 21 | J34: 900 | K34: 1.32 | L34: Có | M34: Có | N34: 200000 | O34: 05, 06, 14, 19, 30, 45, 52, 56 | P34: Báo chí - Truyền Thông, Nhiếp ảnh Helianthus,... | Q34: https://thpttrungvuong.hcm.edu.vn | R34: =TINHKHOANGCACH(Ho_So_Hoc_Sinh!$B$3, C34) -> #NAME? | S34: =IF(ISBLANK(K34), 7, MIN(10, K34 * 4.5)) -> 5.94 | T34: =IF(L34="Có", 10, 6) -> 10 | U34: =Ho_So_Hoc_Sinh!$B$8 -> 10 | V34: =IF(ISBLANK(H34), 7.5, IF(Ho_So_Hoc_Sinh!$B$4>=H34+1, 10, IF(Ho_So_Hoc_Sinh!$B$4<H34-1, 0, 10 - 5*(H34+1-Ho_So_Hoc_Sinh!$B$4)))) -> 1.25 | W34: =IF(D34="Công lập", 10, 5) -> 10 | X34: =MAX(0, 10*(1 - R34/10)) -> #NAME? | Y34: =IF(Ho_So_Hoc_Sinh!$B$5=0, 10, IF(M34="Có", 10, 0)) -> 10 | Z34: =0.154*S34 + 0.152*T34 + 0.145*U34 + 0.144*V34 + 0.14*W34 + 0.138*X34 + 0.128*Y34 -> #NAME? | AA34: =IF(RANK(Z34, $Z$3:$Z$48)=1, "Top 1", IF(RANK(Z34, $Z$3:$Z$48)=2, "Top 2", IF(RANK(Z34, $Z$3:$Z$48)=3, "Top 3", "Khác"))) -> #NAME?
A35: 33 | B35: THPT Phú Nhuận | C35: 5 Hoàng Minh Giám, Phường Đức Nhuận, Tp. HCM | D35: Công lập | E35: Có | F35: 10.809684 | G35: 106.67586 | H35: 24 | I35: 23 | J35: 925 | K35: 2.22 | L35: Có | M35: Có | N35: 200000 | O35: 03, 07, 50, 55, 60-7, 148 | P35: Văn nghệ, Học thuật - Truyền Thông, các CLB thể thao,... | Q35: https://thptphunhuan.hcm.edu.vn | R35: =TINHKHOANGCACH(Ho_So_Hoc_Sinh!$B$3, C35) -> #NAME? | S35: =IF(ISBLANK(K35), 7, MIN(10, K35 * 4.5)) -> 9.99 | T35: =IF(L35="Có", 10, 6) -> 10 | U35: =Ho_So_Hoc_Sinh!$B$8 -> 10 | V35: =IF(ISBLANK(H35), 7.5, IF(Ho_So_Hoc_Sinh!$B$4>=H35+1, 10, IF(Ho_So_Hoc_Sinh!$B$4<H35-1, 0, 10 - 5*(H35+1-Ho_So_Hoc_Sinh!$B$4)))) -> 0 | W35: =IF(D35="Công lập", 10, 5) -> 10 | X35: =MAX(0, 10*(1 - R35/10)) -> #NAME? | Y35: =IF(Ho_So_Hoc_Sinh!$B$5=0, 10, IF(M35="Có", 10, 0)) -> 10 | Z35: =0.154*S35 + 0.152*T35 + 0.145*U35 + 0.144*V35 + 0.14*W35 + 0.138*X35 + 0.128*Y35 -> #NAME? | AA35: =IF(RANK(Z35, $Z$3:$Z$48)=1, "Top 1", IF(RANK(Z35, $Z$3:$Z$48)=2, "Top 2", IF(RANK(Z35, $Z$3:$Z$48)=3, "Top 3", "Khác"))) -> #NAME?
A36: 34 | B36: THPT Trần Phú | C36: 18 Lê Thúc Hoạch, Phường Phú Thọ Hòa, Tp. HCM | D36: Công lập | E36: Có | F36: 10.786951 | G36: 106.62565 | H36: 24.25 | I36: 23.42 | J36: 945 | K36: 2.12 | L36: Có | M36: Có | N36: 200000 | O36: 32, 51, 69 | P36: Văn nghệ, Học thuật - Truyền Thông, các CLB thể thao,... | Q36: https://thpttranphu.hcm.edu.vn | R36: =TINHKHOANGCACH(Ho_So_Hoc_Sinh!$B$3, C36) -> #NAME? | S36: =IF(ISBLANK(K36), 7, MIN(10, K36 * 4.5)) -> 9.54 | T36: =IF(L36="Có", 10, 6) -> 10 | U36: =Ho_So_Hoc_Sinh!$B$8 -> 10 | V36: =IF(ISBLANK(H36), 7.5, IF(Ho_So_Hoc_Sinh!$B$4>=H36+1, 10, IF(Ho_So_Hoc_Sinh!$B$4<H36-1, 0, 10 - 5*(H36+1-Ho_So_Hoc_Sinh!$B$4)))) -> 0 | W36: =IF(D36="Công lập", 10, 5) -> 10 | X36: =MAX(0, 10*(1 - R36/10)) -> #NAME? | Y36: =IF(Ho_So_Hoc_Sinh!$B$5=0, 10, IF(M36="Có", 10, 0)) -> 10 | Z36: =0.154*S36 + 0.152*T36 + 0.145*U36 + 0.144*V36 + 0.14*W36 + 0.138*X36 + 0.128*Y36 -> #NAME? | AA36: =IF(RANK(Z36, $Z$3:$Z$48)=1, "Top 1", IF(RANK(Z36, $Z$3:$Z$48)=2, "Top 2", IF(RANK(Z36, $Z$3:$Z$48)=3, "Top 3", "Khác"))) -> #NAME?
A37: 35 | B37: THPT Tây Thạnh | C37: 27 đường C2, Phường Tây Thạnh, Tp. HCM | D37: Công lập | E37: Có | F37: 10.814332 | G37: 106.62184 | H37: 23.25 | I37: 22 | J37: 1035 | K37: 2.07 | L37: Có | M37: Có | N37: 200000 | O37: 16, 32, 48, 69, 95 | P37: Truyền thông, Nhảy hiện đại, Tiếng Anh,... | Q37: https://thpttaythanh.hcm.edu.vn | R37: =TINHKHOANGCACH(Ho_So_Hoc_Sinh!$B$3, C37) -> #NAME? | S37: =IF(ISBLANK(K37), 7, MIN(10, K37 * 4.5)) -> 9.315 | T37: =IF(L37="Có", 10, 6) -> 10 | U37: =Ho_So_Hoc_Sinh!$B$8 -> 10 | V37: =IF(ISBLANK(H37), 7.5, IF(Ho_So_Hoc_Sinh!$B$4>=H37+1, 10, IF(Ho_So_Hoc_Sinh!$B$4<H37-1, 0, 10 - 5*(H37+1-Ho_So_Hoc_Sinh!$B$4)))) -> 0 | W37: =IF(D37="Công lập", 10, 5) -> 10 | X37: =MAX(0, 10*(1 - R37/10)) -> #NAME? | Y37: =IF(Ho_So_Hoc_Sinh!$B$5=0, 10, IF(M37="Có", 10, 0)) -> 10 | Z37: =0.154*S37 + 0.152*T37 + 0.145*U37 + 0.144*V37 + 0.14*W37 + 0.138*X37 + 0.128*Y37 -> #NAME? | AA37: =IF(RANK(Z37, $Z$3:$Z$48)=1, "Top 1", IF(RANK(Z37, $Z$3:$Z$48)=2, "Top 2", IF(RANK(Z37, $Z$3:$Z$48)=3, "Top 3", "Khác"))) -> #NAME?
A38: 36 | B38: THPT Gia Định | C38: 44 Nguyễn Thượng Hiền, Phường Thạnh Mỹ Tây, Tp. HCM | D38: Công lập | E38: Có | F38: 10.804053 | G38: 106.7183 | H38: 23.5 | I38: 21.75 | J38: 960 | K38: 2.08 | L38: Có | M38: Có | N38: 200000 | O38: 08, 24, 31, 51, 55, 60-7 | P38: Truyền thông trẻ - News Revolution, Dance Group,... | Q38: https://thptgiadinh.hcm.edu.vn | R38: =TINHKHOANGCACH(Ho_So_Hoc_Sinh!$B$3, C38) -> #NAME? | S38: =IF(ISBLANK(K38), 7, MIN(10, K38 * 4.5)) -> 9.36 | T38: =IF(L38="Có", 10, 6) -> 10 | U38: =Ho_So_Hoc_Sinh!$B$8 -> 10 | V38: =IF(ISBLANK(H38), 7.5, IF(Ho_So_Hoc_Sinh!$B$4>=H38+1, 10, IF(Ho_So_Hoc_Sinh!$B$4<H38-1, 0, 10 - 5*(H38+1-Ho_So_Hoc_Sinh!$B$4)))) -> 0 | W38: =IF(D38="Công lập", 10, 5) -> 10 | X38: =MAX(0, 10*(1 - R38/10)) -> #NAME? | Y38: =IF(Ho_So_Hoc_Sinh!$B$5=0, 10, IF(M38="Có", 10, 0)) -> 10 | Z38: =0.154*S38 + 0.152*T38 + 0.145*U38 + 0.144*V38 + 0.14*W38 + 0.138*X38 + 0.128*Y38 -> #NAME? | AA38: =IF(RANK(Z38, $Z$3:$Z$48)=1, "Top 1", IF(RANK(Z38, $Z$3:$Z$48)=2, "Top 2", IF(RANK(Z38, $Z$3:$Z$48)=3, "Top 3", "Khác"))) -> #NAME?
A39: 37 | B39: THPT Võ Thị Sáu | C39: 95 Đinh Tiên Hoàng, Phường Gia Định, Tp. HCM | D39: Công lập | E39: Có | F39: 10.798148 | G39: 106.69609 | H39: 21 | I39: 19.42 | J39: 855 | K39: 1.4 | L39: Có | M39: Có | N39: 200000 | O39: 08, 18, 24, 31, 36, 51, 54, 91 | P39: Văn nghệ, Học thuật - Truyền Thông, các CLB thể thao,... | Q39: https://thptvothisau.hcm.edu.vn | R39: =TINHKHOANGCACH(Ho_So_Hoc_Sinh!$B$3, C39) -> #NAME? | S39: =IF(ISBLANK(K39), 7, MIN(10, K39 * 4.5)) -> 6.3 | T39: =IF(L39="Có", 10, 6) -> 10 | U39: =Ho_So_Hoc_Sinh!$B$8 -> 10 | V39: =IF(ISBLANK(H39), 7.5, IF(Ho_So_Hoc_Sinh!$B$4>=H39+1, 10, IF(Ho_So_Hoc_Sinh!$B$4<H39-1, 0, 10 - 5*(H39+1-Ho_So_Hoc_Sinh!$B$4)))) -> 5 | W39: =IF(D39="Công lập", 10, 5) -> 10 | X39: =MAX(0, 10*(1 - R39/10)) -> #NAME? | Y39: =IF(Ho_So_Hoc_Sinh!$B$5=0, 10, IF(M39="Có", 10, 0)) -> 10 | Z39: =0.154*S39 + 0.152*T39 + 0.145*U39 + 0.144*V39 + 0.14*W39 + 0.138*X39 + 0.128*Y39 -> #NAME? | AA39: =IF(RANK(Z39, $Z$3:$Z$48)=1, "Top 1", IF(RANK(Z39, $Z$3:$Z$48)=2, "Top 2", IF(RANK(Z39, $Z$3:$Z$48)=3, "Top 3", "Khác"))) -> #NAME?
A40: 38 | B40: THPT Phan Đăng Lưu | C40: 27 Nguyễn Văn Đậu, Phường Bình Lợi Trung, Tp. HCM | D40: Công lập | E40: Có | F40: 10.805514 | G40: 106.68702 | H40: 17.5 | I40: 15.67 | J40: 810 | K40: 0.77 | L40: Có | M40: Có | N40: 200000 | O40: 08, 24, 64, 104 | P40: Văn nghệ, Học thuật - Truyền Thông, các CLB thể thao,... | Q40: https://thptphandangluu.hcm.edu.vn | R40: =TINHKHOANGCACH(Ho_So_Hoc_Sinh!$B$3, C40) -> #NAME? | S40: =IF(ISBLANK(K40), 7, MIN(10, K40 * 4.5)) -> 3.465 | T40: =IF(L40="Có", 10, 6) -> 10 | U40: =Ho_So_Hoc_Sinh!$B$8 -> 10 | V40: =IF(ISBLANK(H40), 7.5, IF(Ho_So_Hoc_Sinh!$B$4>=H40+1, 10, IF(Ho_So_Hoc_Sinh!$B$4<H40-1, 0, 10 - 5*(H40+1-Ho_So_Hoc_Sinh!$B$4)))) -> 10 | W40: =IF(D40="Công lập", 10, 5) -> 10 | X40: =MAX(0, 10*(1 - R40/10)) -> #NAME? | Y40: =IF(Ho_So_Hoc_Sinh!$B$5=0, 10, IF(M40="Có", 10, 0)) -> 10 | Z40: =0.154*S40 + 0.152*T40 + 0.145*U40 + 0.144*V40 + 0.14*W40 + 0.138*X40 + 0.128*Y40 -> #NAME? | AA40: =IF(RANK(Z40, $Z$3:$Z$48)=1, "Top 1", IF(RANK(Z40, $Z$3:$Z$48)=2, "Top 2", IF(RANK(Z40, $Z$3:$Z$48)=3, "Top 3", "Khác"))) -> #NAME?
...

Sheet Ho_So_Hoc_Sinh
A1: HỒ SƠ NĂNG LỰC HỌC SINH VÀ BẢNG TRỌNG SỐ 7 TIÊU CHÍ AHP (Ma_Tran_AHP_WebGIS.pdf)
A2: I. THÔNG TIN THIẾT LẬP CÁ NHÂN HÓA HỌC SINH (GIAO DIỆN BẢN ĐỒ TƯƠNG TÁC)
A3: Địa chỉ / Tọa độ nhà học sinh (L_user): | B3: XX1 Đường Đồng Nai, Phường Hòa Hưng, Quận 10, TP.HCM | C3: Nhập vị trí nhà học sinh
A4: Điểm thi tuyển sinh dự kiến (S_user): | B4: 21 | C4: Thang điểm 30 (Toán + Văn + Anh + Ưu tiên)
A5: Nhu cầu bán trú (B_user): | B5: 1 | C5: 1 = CẦN BÁN TRÚ | 0 = KHÔNG CẦN
A6: Loại hình trường ưu tiên: | B6: Công lập | C6: Công lập / Tư thục / Tất cả
A7: Tổ hợp môn tự chọn mong muốn (GDPT 2018): | B7: Lý, Hóa, Sinh, KNTI | C7: KHTN / KHXH / Công nghệ / Nghệ thuật
A8: Điểm đáp ứng tổ hợp môn chuẩn hóa (c_i3): | B8: 10 | C8: Thang điểm 0 - 10
A10: II. KẾT QUẢ ĐỀ XUẤT TOP 3 TRƯỜNG THPT PHÙ HỢP NHẤT THỜI GIAN THỰC
A11: Thứ Hạng | B11: Tên Trường THPT Đề Xuất | C11: Điểm Chuẩn 2026 | D11: Khoảng Cách (km) | E11: Điểm Tương Thích (S_i)
A12: Top 1 | B12: =INDEX(CSDL_Truong!$B$3:$B$48, MATCH("Top 1", CSDL_Truong!$AA$3:$AA$48, 0)) -> #N/A | C12: =INDEX(CSDL_Truong!$H$3:$H$48, MATCH("Top 1", CSDL_Truong!$AA$3:$AA$48, 0)) -> #N/A | D12: =INDEX(CSDL_Truong!$R$3:$R$48, MATCH("Top 1", CSDL_Truong!$AA$3:$AA$48, 0)) -> #N/A | E12: =INDEX(CSDL_Truong!$Z$3:$Z$48, MATCH("Top 1", CSDL_Truong!$AA$3:$AA$48, 0)) -> #N/A
A13: Top 2 | B13: =INDEX(CSDL_Truong!$B$3:$B$48, MATCH("Top 2", CSDL_Truong!$AA$3:$AA$48, 0)) -> #N/A | C13: =INDEX(CSDL_Truong!$H$3:$H$48, MATCH("Top 2", CSDL_Truong!$AA$3:$AA$48, 0)) -> #N/A | D13: =INDEX(CSDL_Truong!$R$3:$R$48, MATCH("Top 2", CSDL_Truong!$AA$3:$AA$48, 0)) -> #N/A | E13: =INDEX(CSDL_Truong!$Z$3:$Z$48, MATCH("Top 2", CSDL_Truong!$AA$3:$AA$48, 0)) -> #N/A
A14: Top 3 | B14: =INDEX(CSDL_Truong!$B$3:$B$48, MATCH("Top 3", CSDL_Truong!$AA$3:$AA$48, 0)) -> #N/A | C14: =INDEX(CSDL_Truong!$H$3:$H$48, MATCH("Top 3", CSDL_Truong!$AA$3:$AA$48, 0)) -> #N/A | D14: =INDEX(CSDL_Truong!$R$3:$R$48, MATCH("Top 3", CSDL_Truong!$AA$3:$AA$48, 0)) -> #N/A | E14: =INDEX(CSDL_Truong!$Z$3:$Z$48, MATCH("Top 3", CSDL_Truong!$AA$3:$AA$48, 0)) -> #N/A
A16: III. BẢNG TRỌNG SỐ VÀ MA TRẬN CHUẨN HÓA AHP 7 TIÊU CHÍ (TỪ Ma_Tran_AHP_WebGIS.pdf)
A17: STT | B17: Danh Mục 7 Tiêu Chí AHP | C17: Điểm Khảo Sat TB (Mean) | D17: Trọng Số W (Eigenvector) | E17: Trọng Số (%)
A18: 1 | B18: Chất lượng đào tạo | C18: 3.968 | D18: 0.154 | E18: 15.40%
A19: 2 | B19: Môi trường & Cơ sở vật chất | C19: 3.905 | D19: 0.152 | E19: 15.15%
A20: 3 | B20: Định hướng học tập (tổ hợp môn) | C20: 3.735 | D20: 0.145 | E20: 14.49%
A21: 4 | B21: Khả năng trúng tuyển | C21: 3.708 | D21: 0.144 | E21: 14.39%
A22: 5 | B22: Tài chính (học phí) | C22: 3.597 | D22: 0.14 | E22: 13.96%
A23: 6 | B23: Vị trí & Khả năng di chuyển | C23: 3.549 | D23: 0.138 | E23: 13.77%
A24: 7 | B24: Mô hình học tập (bán trú) | C24: 3.308 | D24: 0.128 | E24: 12.84%
A25: Kiểm định tính nhất quán AHP: λ_max = 7.000 | n = 7 | CI = 0.000 | RI = 1.320 | CR = 0.0 (< 0.1) -> ĐẠT ĐỘ NHẤT QUÁN TUYỆT ĐỐI
